fn main()
{
    try
    {
        throw exception();
    }
    catch
    {
        print("test");
    }
}